Loading checkpoint shards:   0%|          | 0/2 [00:00<?, ?it/s]Loading checkpoint shards:  50%|█████     | 1/2 [00:08<00:08,  8.16s/it]Loading checkpoint shards: 100%|██████████| 2/2 [00:10<00:00,  4.97s/it]Loading checkpoint shards: 100%|██████████| 2/2 [00:10<00:00,  5.45s/it]
/home/estudiante1/venvs/vllms/lib/python3.10/site-packages/bitsandbytes/nn/modules.py:451: UserWarning: Input type into Linear4bit is torch.float16, but bnb_4bit_compute_dtype=torch.float32 (default). This will lead to slow inference or training speed.
  warnings.warn(
No error handlers are registered, logging exception.
Traceback (most recent call last):
  File "/home/estudiante1/venvs/vllms/lib/python3.10/site-packages/httpx/_transports/default.py", line 101, in map_httpcore_exceptions
    yield
  File "/home/estudiante1/venvs/vllms/lib/python3.10/site-packages/httpx/_transports/default.py", line 394, in handle_async_request
    resp = await self._pool.handle_async_request(req)
  File "/home/estudiante1/venvs/vllms/lib/python3.10/site-packages/httpcore/_async/connection_pool.py", line 256, in handle_async_request
    raise exc from None
  File "/home/estudiante1/venvs/vllms/lib/python3.10/site-packages/httpcore/_async/connection_pool.py", line 236, in handle_async_request
    response = await connection.handle_async_request(
  File "/home/estudiante1/venvs/vllms/lib/python3.10/site-packages/httpcore/_async/connection.py", line 103, in handle_async_request
    return await self._connection.handle_async_request(request)
  File "/home/estudiante1/venvs/vllms/lib/python3.10/site-packages/httpcore/_async/http11.py", line 136, in handle_async_request
    raise exc
  File "/home/estudiante1/venvs/vllms/lib/python3.10/site-packages/httpcore/_async/http11.py", line 106, in handle_async_request
    ) = await self._receive_response_headers(**kwargs)
  File "/home/estudiante1/venvs/vllms/lib/python3.10/site-packages/httpcore/_async/http11.py", line 177, in _receive_response_headers
    event = await self._receive_event(timeout=timeout)
  File "/home/estudiante1/venvs/vllms/lib/python3.10/site-packages/httpcore/_async/http11.py", line 217, in _receive_event
    data = await self._network_stream.read(
  File "/home/estudiante1/venvs/vllms/lib/python3.10/site-packages/httpcore/_backends/anyio.py", line 32, in read
    with map_exceptions(exc_map):
  File "/usr/lib/python3.10/contextlib.py", line 153, in __exit__
    self.gen.throw(typ, value, traceback)
  File "/home/estudiante1/venvs/vllms/lib/python3.10/site-packages/httpcore/_exceptions.py", line 14, in map_exceptions
    raise to_exc(exc) from exc
httpcore.ReadError

The above exception was the direct cause of the following exception:

Traceback (most recent call last):
  File "/home/estudiante1/venvs/vllms/lib/python3.10/site-packages/telegram/request/_httpxrequest.py", line 277, in do_request
    res = await self._client.request(
  File "/home/estudiante1/venvs/vllms/lib/python3.10/site-packages/httpx/_client.py", line 1540, in request
    return await self.send(request, auth=auth, follow_redirects=follow_redirects)
  File "/home/estudiante1/venvs/vllms/lib/python3.10/site-packages/httpx/_client.py", line 1629, in send
    response = await self._send_handling_auth(
  File "/home/estudiante1/venvs/vllms/lib/python3.10/site-packages/httpx/_client.py", line 1657, in _send_handling_auth
    response = await self._send_handling_redirects(
  File "/home/estudiante1/venvs/vllms/lib/python3.10/site-packages/httpx/_client.py", line 1694, in _send_handling_redirects
    response = await self._send_single_request(request)
  File "/home/estudiante1/venvs/vllms/lib/python3.10/site-packages/httpx/_client.py", line 1730, in _send_single_request
    response = await transport.handle_async_request(request)
  File "/home/estudiante1/venvs/vllms/lib/python3.10/site-packages/httpx/_transports/default.py", line 393, in handle_async_request
    with map_httpcore_exceptions():
  File "/usr/lib/python3.10/contextlib.py", line 153, in __exit__
    self.gen.throw(typ, value, traceback)
  File "/home/estudiante1/venvs/vllms/lib/python3.10/site-packages/httpx/_transports/default.py", line 118, in map_httpcore_exceptions
    raise mapped_exc(message) from exc
httpx.ReadError

The above exception was the direct cause of the following exception:

Traceback (most recent call last):
  File "/home/estudiante1/venvs/vllms/lib/python3.10/site-packages/telegram/ext/_utils/networkloop.py", line 115, in network_retry_loop
    if not await do_action():
  File "/home/estudiante1/venvs/vllms/lib/python3.10/site-packages/telegram/ext/_utils/networkloop.py", line 108, in do_action
    return action_cb_task.result()
  File "/usr/lib/python3.10/asyncio/futures.py", line 201, in result
    raise self._exception.with_traceback(self._exception_tb)
  File "/usr/lib/python3.10/asyncio/tasks.py", line 232, in __step
    result = coro.send(None)
  File "/home/estudiante1/venvs/vllms/lib/python3.10/site-packages/telegram/ext/_updater.py", line 335, in polling_action_cb
    updates = await self.bot.get_updates(
  File "/home/estudiante1/venvs/vllms/lib/python3.10/site-packages/telegram/ext/_extbot.py", line 658, in get_updates
    updates = await super().get_updates(
  File "/home/estudiante1/venvs/vllms/lib/python3.10/site-packages/telegram/_bot.py", line 4593, in get_updates
    await self._post(
  File "/home/estudiante1/venvs/vllms/lib/python3.10/site-packages/telegram/_bot.py", line 691, in _post
    return await self._do_post(
  File "/home/estudiante1/venvs/vllms/lib/python3.10/site-packages/telegram/ext/_extbot.py", line 362, in _do_post
    return await super()._do_post(
  File "/home/estudiante1/venvs/vllms/lib/python3.10/site-packages/telegram/_bot.py", line 720, in _do_post
    result = await request.post(
  File "/home/estudiante1/venvs/vllms/lib/python3.10/site-packages/telegram/request/_baserequest.py", line 197, in post
    result = await self._request_wrapper(
  File "/home/estudiante1/venvs/vllms/lib/python3.10/site-packages/telegram/request/_baserequest.py", line 304, in _request_wrapper
    code, payload = await self.do_request(
  File "/home/estudiante1/venvs/vllms/lib/python3.10/site-packages/telegram/request/_httpxrequest.py", line 301, in do_request
    raise NetworkError(f"httpx.{err.__class__.__name__}: {err}") from err
telegram.error.NetworkError: httpx.ReadError: 
